<?xml version="1.0" ?>
<!-- =================================================================================== -->
<!-- |    This document was autogenerated by xacro from telos.xacro                    | -->
<!-- |    EDITING THIS FILE BY HAND IS NOT RECOMMENDED                                 | -->
<!-- =================================================================================== -->
<robot name="telos">
  <!-- ros_control plugin -->
  <gazebo>
    <plugin filename="libgazebo_ros_control.so" name="gazebo_ros_control">
      <robotNamespace>/telos</robotNamespace>
      <robotSimType>gazebo_ros_control/DefaultRobotHWSim</robotSimType>
    </plugin>
  </gazebo>
  <gazebo>
    <plugin filename="move_plugin.so" name="move"/>
  </gazebo>
  <!-- <xacro:property name="thighMass" value="0.4"/> -->
  <material name="black">
    <color rgba="0.0 0.0 0.0 1.0"/>
  </material>
  <material name="blue">
    <color rgba="0.0 0.0 0.8 1.0"/>
  </material>
  <material name="green">
    <color rgba="0.0 0.8 0.0 1.0"/>
  </material>
  <material name="grey">
    <color rgba="0.2 0.2 0.2 1.0"/>
  </material>
  <material name="orange">
    <color rgba="1.0 0.4235294117647059 0.0392156862745098 1.0"/>
  </material>
  <material name="brown">
    <color rgba="0.8705882352941177 0.8117647058823529 0.7647058823529411 1.0"/>
  </material>
  <material name="red">
    <color rgba="0.8 0.0 0.0 1.0"/>
  </material>
  <material name="white">
    <color rgba="1.0 1.0 1.0 1.0"/>
  </material>
  <!-- <link name="base_link"/>
    
<joint name="fixed" type="fixed">
    <parent link="base_link"/>
    ACHTUNG
    <child link="corpus"/>
    <origin xyz="0.0 0.0 0.0"/>
</joint> -->
  <link name="base_link">
    <visual>
      <geometry>
        <box size=".1 0.39 0.052"/>
        <box size="0.1 0.39 0.052"/>
      </geometry>
      <origin rpy="0.0 0.0 0.0" xyz="0 0 0"/>
      <material name="white"/>
    </visual>
    <collision>
      <geometry>
        <box size="0.1 0.39 0.052"/>
      </geometry>
    </collision>
    <inertial>
      <mass value="2.5"/>
      <inertia ixx="0.032250833" ixy="0.0" ixz="0.0" iyy="0.002646667" iyz="0.0" izz="0.033770833"/>
    </inertial>
  </link>
  <link name="right_front_rotator">
    <visual>
      <geometry>
        <box size="1e-13 1e-13 1e-13"/>
      </geometry>
      <origin xyz="0 0 0"/>
      <material name="black"/>
    </visual>
    <!-- <collision>
            <geometry>
                <box size="${corpusWidth} ${corpusDepth} ${corpusHeight}"/> 
            </geometry>
        </collision> -->
    <inertial>
      <mass value="0.0001"/>
      <inertia ixx="0.00000000001" ixy="0.0" ixz="0.0" iyy="0.00000000001" iyz="0.0" izz="0.00000000001"/>
    </inertial>
  </link>
  <joint name="corpus_to_right_front_rotator" type="revolute">
    <axis xyz="0.0 1 0.0"/>
    <limit effort="1000.0" lower="-1.253294755" upper="1.253294755" velocity="0.5"/>
    <parent link="base_link"/>
    <child link="right_front_rotator"/>
    <origin xyz="0.06 0.15 0"/>
  </joint>
  <transmission name="right_front_rotator_transmission">
    <type>transmission_interface/SimpleTransmission</type>
    <joint name="corpus_to_right_front_rotator">
      <hardwareInterface>hardware_interface/EffortJointInterface</hardwareInterface>
    </joint>
    <actuator name="right_front_motor">
      <mechanicalReduction>&quot;1.88&quot;</mechanicalReduction>
      <hardwareInterface>hardware_interface/EffortJointInterface</hardwareInterface>
    </actuator>
  </transmission>
  <link name="right_front_thigh">
    <visual>
      <geometry>
        <box size="0.02 0.145 0.02"/>
      </geometry>
      <origin xyz="0 -0.0625 0"/>
      <material name="blue"/>
    </visual>
    <collision>
      <geometry>
        <box size="0.02 0.145 0.02"/>
      </geometry>
    </collision>
    <inertial>
      <mass value="0.8"/>
      <!-- <inertia ixx="0.000704167" ixy="0.0" ixz="0.0"
         iyy="0.0000532292" iyz="0.0" izz="0.0000704167"/> -->
      <inertia ixx="0.000904167" ixy="0.0" ixz="0.0" iyy="0.0000732292" iyz="0.0" izz="0.0000904167"/>
    </inertial>
  </link>
  <joint name="rotator_to_right_front_thigh" type="revolute">
    <axis xyz="1 0.0 0.0"/>
    <limit effort="1000.0" lower="-1.253294755" upper="1.253294755" velocity="0.5"/>
    <parent link="right_front_rotator"/>
    <child link="right_front_thigh"/>
    <origin rpy="0.785 0.0 0.0" xyz="0.0 0.0 0.0"/>
  </joint>
  <transmission name="right_front_thigh_transmission">
    <type>transmission_interface/SimpleTransmission</type>
    <joint name="rotator_to_right_front_thigh">
      <hardwareInterface>hardware_interface/EffortJointInterface</hardwareInterface>
    </joint>
    <actuator name="right_front_thigh_motor">
      <mechanicalReduction>&quot;1.88&quot;</mechanicalReduction>
      <hardwareInterface>hardware_interface/EffortJointInterface</hardwareInterface>
    </actuator>
  </transmission>
  <link name="right_front_feet">
    <visual>
      <geometry>
        <box size="0.02 0.145 0.02"/>
      </geometry>
      <origin xyz="0.0 -0.0625 0.0"/>
      <material name="black"/>
    </visual>
    <collision>
      <geometry>
        <box size="0.02 0.145 0.02"/>
      </geometry>
    </collision>
    <inertial>
      <mass value="0.1"/>
      <!-- <inertia ixx="0.000704167" ixy="0.0" ixz="0.0"
         iyy="0.000532292" iyz="0.0" izz="0.000704167"/> -->
      <inertia ixx="0,000088021" ixy="0.0" ixz="0.0" iyy="0.665365" iyz="0.0" izz="0,000088021"/>
    </inertial>
  </link>
  <joint name="thigh_to_right_front_feet" type="revolute">
    <axis xyz="1 0.0 0.0"/>
    <limit effort="1000.0" lower="-0.785" upper="0.785" velocity="0.5"/>
    <parent link="right_front_thigh"/>
    <child link="right_front_feet"/>
    <origin rpy="1.57 0.0 0.0" xyz="0 -0.125 0"/>
  </joint>
  <transmission name="right_front_feet_transmission">
    <type>transmission_interface/SimpleTransmission</type>
    <joint name="thigh_to_right_front_feet">
      <hardwareInterface>hardware_interface/EffortJointInterface</hardwareInterface>
    </joint>
    <actuator name="right_front_feet_motor">
      <mechanicalReduction>&quot;1.5&quot;</mechanicalReduction>
      <hardwareInterface>hardware_interface/EffortJointInterface</hardwareInterface>
    </actuator>
  </transmission>
  <link name="left_front_rotator">
    <visual>
      <geometry>
        <box size="1e-13 1e-13 1e-13"/>
      </geometry>
      <origin xyz="0 0 0"/>
      <material name="black"/>
    </visual>
    <!-- <collision>
            <geometry>
                <box size="${corpusWidth} ${corpusDepth} ${corpusHeight}"/> 
            </geometry>
        </collision> -->
    <inertial>
      <mass value="0.0001"/>
      <inertia ixx="0.00000000001" ixy="0.0" ixz="0.0" iyy="0.00000000001" iyz="0.0" izz="0.00000000001"/>
    </inertial>
  </link>
  <joint name="corpus_to_left_front_rotator" type="revolute">
    <axis xyz="0.0 1 0.0"/>
    <limit effort="1000.0" lower="-1.253294755" upper="1.253294755" velocity="0.5"/>
    <parent link="base_link"/>
    <child link="left_front_rotator"/>
    <origin xyz="-0.06 0.15 0"/>
  </joint>
  <transmission name="left_front_rotator_transmission">
    <type>transmission_interface/SimpleTransmission</type>
    <joint name="corpus_to_left_front_rotator">
      <hardwareInterface>hardware_interface/EffortJointInterface</hardwareInterface>
    </joint>
    <actuator name="left_front_motor">
      <mechanicalReduction>&quot;1.88&quot;</mechanicalReduction>
      <hardwareInterface>hardware_interface/EffortJointInterface</hardwareInterface>
    </actuator>
  </transmission>
  <link name="left_front_thigh">
    <visual>
      <geometry>
        <box size="0.02 0.145 0.02"/>
      </geometry>
      <origin xyz="0 -0.0625 0"/>
      <material name="blue"/>
    </visual>
    <collision>
      <geometry>
        <box size="0.02 0.145 0.02"/>
      </geometry>
    </collision>
    <inertial>
      <mass value="0.8"/>
      <!-- <inertia ixx="0.000704167" ixy="0.0" ixz="0.0"
         iyy="0.0000532292" iyz="0.0" izz="0.0000704167"/> -->
      <inertia ixx="0.000904167" ixy="0.0" ixz="0.0" iyy="0.0000732292" iyz="0.0" izz="0.0000904167"/>
    </inertial>
  </link>
  <joint name="rotator_to_left_front_thigh" type="revolute">
    <axis xyz="1 0.0 0.0"/>
    <limit effort="1000.0" lower="-1.253294755" upper="1.253294755" velocity="0.5"/>
    <parent link="left_front_rotator"/>
    <child link="left_front_thigh"/>
    <origin rpy="0.785 0.0 0.0" xyz="0.0 0.0 0.0"/>
  </joint>
  <transmission name="left_front_thigh_transmission">
    <type>transmission_interface/SimpleTransmission</type>
    <joint name="rotator_to_left_front_thigh">
      <hardwareInterface>hardware_interface/EffortJointInterface</hardwareInterface>
    </joint>
    <actuator name="left_front_thigh_motor">
      <mechanicalReduction>&quot;1.88&quot;</mechanicalReduction>
      <hardwareInterface>hardware_interface/EffortJointInterface</hardwareInterface>
    </actuator>
  </transmission>
  <link name="left_front_feet">
    <visual>
      <geometry>
        <box size="0.02 0.145 0.02"/>
      </geometry>
      <origin xyz="0.0 -0.0625 0.0"/>
      <material name="black"/>
    </visual>
    <collision>
      <geometry>
        <box size="0.02 0.145 0.02"/>
      </geometry>
    </collision>
    <inertial>
      <mass value="0.1"/>
      <!-- <inertia ixx="0.000704167" ixy="0.0" ixz="0.0"
         iyy="0.000532292" iyz="0.0" izz="0.000704167"/> -->
      <inertia ixx="0,000088021" ixy="0.0" ixz="0.0" iyy="0.665365" iyz="0.0" izz="0,000088021"/>
    </inertial>
  </link>
  <joint name="thigh_to_left_front_feet" type="revolute">
    <axis xyz="1 0.0 0.0"/>
    <limit effort="1000.0" lower="-0.785" upper="0.785" velocity="0.5"/>
    <parent link="left_front_thigh"/>
    <child link="left_front_feet"/>
    <origin rpy="1.57 0.0 0.0" xyz="0 -0.125 0"/>
  </joint>
  <transmission name="left_front_feet_transmission">
    <type>transmission_interface/SimpleTransmission</type>
    <joint name="thigh_to_left_front_feet">
      <hardwareInterface>hardware_interface/EffortJointInterface</hardwareInterface>
    </joint>
    <actuator name="left_front_feet_motor">
      <mechanicalReduction>&quot;1.5&quot;</mechanicalReduction>
      <hardwareInterface>hardware_interface/EffortJointInterface</hardwareInterface>
    </actuator>
  </transmission>
  <link name="right_back_rotator">
    <visual>
      <geometry>
        <box size="1e-13 1e-13 1e-13"/>
      </geometry>
      <origin xyz="0 0 0"/>
      <material name="black"/>
    </visual>
    <!-- <collision>
            <geometry>
                <box size="${corpusWidth} ${corpusDepth} ${corpusHeight}"/> 
            </geometry>
        </collision> -->
    <inertial>
      <mass value="0.0001"/>
      <inertia ixx="0.00000000001" ixy="0.0" ixz="0.0" iyy="0.00000000001" iyz="0.0" izz="0.00000000001"/>
    </inertial>
  </link>
  <joint name="corpus_to_right_back_rotator" type="revolute">
    <axis xyz="0.0 1 0.0"/>
    <limit effort="1000.0" lower="-1.253294755" upper="1.253294755" velocity="0.5"/>
    <parent link="base_link"/>
    <child link="right_back_rotator"/>
    <origin xyz="0.06 -0.15 0"/>
  </joint>
  <transmission name="right_back_rotator_transmission">
    <type>transmission_interface/SimpleTransmission</type>
    <joint name="corpus_to_right_back_rotator">
      <hardwareInterface>hardware_interface/EffortJointInterface</hardwareInterface>
    </joint>
    <actuator name="right_back_motor">
      <mechanicalReduction>&quot;1.88&quot;</mechanicalReduction>
      <hardwareInterface>hardware_interface/EffortJointInterface</hardwareInterface>
    </actuator>
  </transmission>
  <link name="right_back_thigh">
    <visual>
      <geometry>
        <box size="0.02 0.145 0.02"/>
      </geometry>
      <origin xyz="0 -0.0625 0"/>
      <material name="blue"/>
    </visual>
    <collision>
      <geometry>
        <box size="0.02 0.145 0.02"/>
      </geometry>
    </collision>
    <inertial>
      <mass value="0.8"/>
      <!-- <inertia ixx="0.000704167" ixy="0.0" ixz="0.0"
         iyy="0.0000532292" iyz="0.0" izz="0.0000704167"/> -->
      <inertia ixx="0.000904167" ixy="0.0" ixz="0.0" iyy="0.0000732292" iyz="0.0" izz="0.0000904167"/>
    </inertial>
  </link>
  <joint name="rotator_to_right_back_thigh" type="revolute">
    <axis xyz="1 0.0 0.0"/>
    <limit effort="1000.0" lower="-1.253294755" upper="1.253294755" velocity="0.5"/>
    <parent link="right_back_rotator"/>
    <child link="right_back_thigh"/>
    <origin rpy="0.785 0.0 0.0" xyz="0.0 0.0 0.0"/>
  </joint>
  <transmission name="right_back_thigh_transmission">
    <type>transmission_interface/SimpleTransmission</type>
    <joint name="rotator_to_right_back_thigh">
      <hardwareInterface>hardware_interface/EffortJointInterface</hardwareInterface>
    </joint>
    <actuator name="right_back_thigh_motor">
      <mechanicalReduction>&quot;1.88&quot;</mechanicalReduction>
      <hardwareInterface>hardware_interface/EffortJointInterface</hardwareInterface>
    </actuator>
  </transmission>
  <link name="right_back_feet">
    <visual>
      <geometry>
        <box size="0.02 0.145 0.02"/>
      </geometry>
      <origin xyz="0.0 -0.0625 0.0"/>
      <material name="black"/>
    </visual>
    <collision>
      <geometry>
        <box size="0.02 0.145 0.02"/>
      </geometry>
    </collision>
    <inertial>
      <mass value="0.1"/>
      <!-- <inertia ixx="0.000704167" ixy="0.0" ixz="0.0"
         iyy="0.000532292" iyz="0.0" izz="0.000704167"/> -->
      <inertia ixx="0,000088021" ixy="0.0" ixz="0.0" iyy="0.665365" iyz="0.0" izz="0,000088021"/>
    </inertial>
  </link>
  <joint name="thigh_to_right_back_feet" type="revolute">
    <axis xyz="1 0.0 0.0"/>
    <limit effort="1000.0" lower="-0.785" upper="0.785" velocity="0.5"/>
    <parent link="right_back_thigh"/>
    <child link="right_back_feet"/>
    <origin rpy="1.57 0.0 0.0" xyz="0 -0.125 0"/>
  </joint>
  <transmission name="right_back_feet_transmission">
    <type>transmission_interface/SimpleTransmission</type>
    <joint name="thigh_to_right_back_feet">
      <hardwareInterface>hardware_interface/EffortJointInterface</hardwareInterface>
    </joint>
    <actuator name="right_back_feet_motor">
      <mechanicalReduction>&quot;1.5&quot;</mechanicalReduction>
      <hardwareInterface>hardware_interface/EffortJointInterface</hardwareInterface>
    </actuator>
  </transmission>
  <link name="left_back_rotator">
    <visual>
      <geometry>
        <box size="1e-13 1e-13 1e-13"/>
      </geometry>
      <origin xyz="0 0 0"/>
      <material name="black"/>
    </visual>
    <!-- <collision>
            <geometry>
                <box size="${corpusWidth} ${corpusDepth} ${corpusHeight}"/> 
            </geometry>
        </collision> -->
    <inertial>
      <mass value="0.0001"/>
      <inertia ixx="0.00000000001" ixy="0.0" ixz="0.0" iyy="0.00000000001" iyz="0.0" izz="0.00000000001"/>
    </inertial>
  </link>
  <joint name="corpus_to_left_back_rotator" type="revolute">
    <axis xyz="0.0 1 0.0"/>
    <limit effort="1000.0" lower="-1.253294755" upper="1.253294755" velocity="0.5"/>
    <parent link="base_link"/>
    <child link="left_back_rotator"/>
    <origin xyz="-0.06 -0.15 0"/>
  </joint>
  <transmission name="left_back_rotator_transmission">
    <type>transmission_interface/SimpleTransmission</type>
    <joint name="corpus_to_left_back_rotator">
      <hardwareInterface>hardware_interface/EffortJointInterface</hardwareInterface>
    </joint>
    <actuator name="left_back_motor">
      <mechanicalReduction>&quot;1.88&quot;</mechanicalReduction>
      <hardwareInterface>hardware_interface/EffortJointInterface</hardwareInterface>
    </actuator>
  </transmission>
  <link name="left_back_thigh">
    <visual>
      <geometry>
        <box size="0.02 0.145 0.02"/>
      </geometry>
      <origin xyz="0 -0.0625 0"/>
      <material name="blue"/>
    </visual>
    <collision>
      <geometry>
        <box size="0.02 0.145 0.02"/>
      </geometry>
    </collision>
    <inertial>
      <mass value="0.8"/>
      <!-- <inertia ixx="0.000704167" ixy="0.0" ixz="0.0"
         iyy="0.0000532292" iyz="0.0" izz="0.0000704167"/> -->
      <inertia ixx="0.000904167" ixy="0.0" ixz="0.0" iyy="0.0000732292" iyz="0.0" izz="0.0000904167"/>
    </inertial>
  </link>
  <joint name="rotator_to_left_back_thigh" type="revolute">
    <axis xyz="1 0.0 0.0"/>
    <limit effort="1000.0" lower="-1.253294755" upper="1.253294755" velocity="0.5"/>
    <parent link="left_back_rotator"/>
    <child link="left_back_thigh"/>
    <origin rpy="0.785 0.0 0.0" xyz="0.0 0.0 0.0"/>
  </joint>
  <transmission name="left_back_thigh_transmission">
    <type>transmission_interface/SimpleTransmission</type>
    <joint name="rotator_to_left_back_thigh">
      <hardwareInterface>hardware_interface/EffortJointInterface</hardwareInterface>
    </joint>
    <actuator name="left_back_thigh_motor">
      <mechanicalReduction>&quot;1.88&quot;</mechanicalReduction>
      <hardwareInterface>hardware_interface/EffortJointInterface</hardwareInterface>
    </actuator>
  </transmission>
  <link name="left_back_feet">
    <visual>
      <geometry>
        <box size="0.02 0.145 0.02"/>
      </geometry>
      <origin xyz="0.0 -0.0625 0.0"/>
      <material name="black"/>
    </visual>
    <collision>
      <geometry>
        <box size="0.02 0.145 0.02"/>
      </geometry>
    </collision>
    <inertial>
      <mass value="0.1"/>
      <!-- <inertia ixx="0.000704167" ixy="0.0" ixz="0.0"
         iyy="0.000532292" iyz="0.0" izz="0.000704167"/> -->
      <inertia ixx="0,000088021" ixy="0.0" ixz="0.0" iyy="0.665365" iyz="0.0" izz="0,000088021"/>
    </inertial>
  </link>
  <joint name="thigh_to_left_back_feet" type="revolute">
    <axis xyz="1 0.0 0.0"/>
    <limit effort="1000.0" lower="-0.785" upper="0.785" velocity="0.5"/>
    <parent link="left_back_thigh"/>
    <child link="left_back_feet"/>
    <origin rpy="1.57 0.0 0.0" xyz="0 -0.125 0"/>
  </joint>
  <transmission name="left_back_feet_transmission">
    <type>transmission_interface/SimpleTransmission</type>
    <joint name="thigh_to_left_back_feet">
      <hardwareInterface>hardware_interface/EffortJointInterface</hardwareInterface>
    </joint>
    <actuator name="left_back_feet_motor">
      <mechanicalReduction>&quot;1.5&quot;</mechanicalReduction>
      <hardwareInterface>hardware_interface/EffortJointInterface</hardwareInterface>
    </actuator>
  </transmission>
</robot>

